<?xml version="1.0"?>
<robot name="quadruped_robot" xmlns:xacro="http://ros.org/wiki/xacro">
  <link
    name="body_link">
    <inertial>
      <origin
        xyz="-0.0104808628759405 0.00224834175396924 -0.0052263545122232"
        rpy="0 0 0" />
      <mass
        value="0.377252605852233" />
      <inertia
        ixx="0.000418954363866351"
        ixy="7.511988833675E-07"
        ixz="4.09865880530585E-06"
        iyy="0.000433125892291076"
        iyz="1.41818186723719E-08"
        izz="0.000626600145088028" />
    </inertial>
    <visual>
      <origin
        xyz="0 0 0"
        rpy="0 0 0" />
      <geometry>
        <mesh
          filename="package://quadruped_robot/meshes/body_link.STL" />
      </geometry>
      <material
        name="">
        <color
          rgba="0.752941176470588 0.752941176470588 0.752941176470588 1" />
      </material>
    </visual>
    <collision>
      <origin
        xyz="0 0 0"
        rpy="0 0 0" />
      <geometry>
        <mesh
          filename="package://quadruped_robot/meshes/body_link.STL" />
      </geometry>
    </collision>
  </link>
  <link
    name="frs_link">
    <inertial>
      <origin
        xyz="0.0163093960247798 -0.00505196516998213 -0.0274849143348015"
        rpy="0 0 0" />
      <mass
        value="0.0385204737997983" />
      <inertia
        ixx="8.71211945498261E-06"
        ixy="4.10847903075371E-08"
        ixz="-1.78152149761969E-10"
        iyy="5.13274302177548E-06"
        iyz="2.46917233525575E-07"
        izz="7.80614050595697E-06" />
    </inertial>
    <visual>
      <origin
        xyz="0 0 0"
        rpy="0 0 0" />
      <geometry>
        <mesh
          filename="package://quadruped_robot/meshes/frs_link.STL" />
      </geometry>
      <material
        name="">
        <color
          rgba="0.2 0.2 0.2 1" />
      </material>
    </visual>
    <collision>
      <origin
        xyz="0 0 0"
        rpy="0 0 0" />
      <geometry>
        <mesh
          filename="package://quadruped_robot/meshes/frs_link.STL" />
      </geometry>
    </collision>
  </link>
  <joint
    name="frs_joint"
    type="revolute">
    <origin
      xyz="0.0692381468948904 -0.036563051924115 0"
      rpy="1.5707963267949 0 -1.5707963267949" />
    <parent
      link="body_link" />
    <child
      link="frs_link" />
    <axis
      xyz="0 0 -1" />
    <limit
      lower="-1.04"
      upper="1.04"
      effort="15"
      velocity="0.1" />
    <dynamics
      friction="0.1" />
  </joint>
  <link
    name="fre_link">
    <inertial>
      <origin
        xyz="-0.0348617587747592 -0.0401535760436038 0.0318877501407731"
        rpy="0 0 0" />
      <mass
        value="0.0887724177691983" />
      <inertia
        ixx="5.33826954697177E-05"
        ixy="-4.01657420177436E-05"
        ixz="2.23436712556012E-07"
        iyy="5.54056136320405E-05"
        iyz="1.34175995588459E-06"
        izz="9.09432485780886E-05" />
    </inertial>
    <visual>
      <origin
        xyz="0 0 0"
        rpy="0 0 0" />
      <geometry>
        <mesh
          filename="package://quadruped_robot/meshes/fre_link.STL" />
      </geometry>
      <material
        name="">
        <color
          rgba="0.2 0.2 0.2 1" />
      </material>
    </visual>
    <collision>
      <origin
        xyz="0 0 0"
        rpy="0 0 0" />
      <geometry>
        <mesh
          filename="package://quadruped_robot/meshes/fre_link.STL" />
      </geometry>
    </collision>
  </link>
  <joint
    name="fre_joint"
    type="revolute">
    <origin
      xyz="0.026 2.5E-05 -0.0292"
      rpy="0 1.5708 0" />
    <parent
      link="frs_link" />
    <child
      link="fre_link" />
    <axis
      xyz="0 0 -1" />
    <limit
      lower="-1.57"
      upper="1.57"
      effort="15"
      velocity="0.1" />
    <dynamics
      friction="0.1" />
  </joint>
  <link
    name="frw_link">
    <inertial>
      <origin
        xyz="0.0332213053367797 -0.0366951699334233 0.0245753331663336"
        rpy="0 0 0" />
      <mass
        value="0.0364534542471395" />
      <inertia
        ixx="3.24424063682796E-05"
        ixy="2.86763548564017E-05"
        ixz="2.62022167693562E-06"
        iyy="3.69606897466966E-05"
        iyz="-2.37232854652557E-06"
        izz="6.2793297163366E-05" />
    </inertial>
    <visual>
      <origin
        xyz="0 0 0"
        rpy="0 0 0" />
      <geometry>
        <mesh
          filename="package://quadruped_robot/meshes/frw_link.STL" />
      </geometry>
      <material
        name="">
        <color
          rgba="0.2 0.2 0.2 1" />
      </material>
    </visual>
    <collision>
      <origin
        xyz="0 0 0"
        rpy="0 0 0" />
      <geometry>
        <mesh
          filename="package://quadruped_robot/meshes/frw_link.STL" />
      </geometry>
    </collision>
  </link>
  <joint
    name="frw_joint"
    type="revolute">
    <origin
      xyz="-0.0662802231881607 -0.0864763481921448 0.0120000007629388"
      rpy="0 0 0" />
    <parent
      link="fre_link" />
    <child
      link="frw_link" />
    <axis
      xyz="0 0 -1" />
    <limit
      lower="-1.57"
      upper="1.57"
      effort="15"
      velocity="0.1" />
    <dynamics
      friction="0.1" />
  </joint>
  <link
    name="rrs_link">
    <inertial>
      <origin
        xyz="-0.0163095359847977 -0.00505178186569167 -0.0274848378346865"
        rpy="0 0 0" />
      <mass
        value="0.0385206604865966" />
      <inertia
        ixx="8.71226998638339E-06"
        ixy="-4.115482434391E-08"
        ixz="1.23274505723502E-10"
        iyy="5.13285337559971E-06"
        iyz="2.46844401583443E-07"
        izz="7.80628697106784E-06" />
    </inertial>
    <visual>
      <origin
        xyz="0 0 0"
        rpy="0 0 0" />
      <geometry>
        <mesh
          filename="package://quadruped_robot/meshes/rrs_link.STL" />
      </geometry>
      <material
        name="">
        <color
          rgba="0.2 0.2 0.2 1" />
      </material>
    </visual>
    <collision>
      <origin
        xyz="0 0 0"
        rpy="0 0 0" />
      <geometry>
        <mesh
          filename="package://quadruped_robot/meshes/rrs_link.STL" />
      </geometry>
    </collision>
  </link>
  <joint
    name="rrs_joint"
    type="revolute">
    <origin
      xyz="-0.0677618531051057 -0.0365628086889124 0"
      rpy="1.5707963267949 0 1.5707963267949" />
    <parent
      link="body_link" />
    <child
      link="rrs_link" />
    <axis
      xyz="0 0 -1" />
    <limit
      lower="-1.04"
      upper="1.04"
      effort="15"
      velocity="0.1" />
    <dynamics
      friction="0.1" />
  </joint>
  <link
    name="rre_link">
    <inertial>
      <origin
        xyz="-0.0353949234320192 -0.0396843949308324 0.0318877499657951"
        rpy="0 0 0" />
      <mass
        value="0.0887724191485841" />
      <inertia
        ixx="5.23102779505384E-05"
        ixy="-4.01243985782808E-05"
        ixz="2.41336508654976E-07"
        iyy="5.64780329923361E-05"
        iyz="1.33865580603777E-06"
        izz="9.09432493810381E-05" />
    </inertial>
    <visual>
      <origin
        xyz="0 0 0"
        rpy="0 0 0" />
      <geometry>
        <mesh
          filename="package://quadruped_robot/meshes/rre_link.STL" />
      </geometry>
      <material
        name="">
        <color
          rgba="0.2 0.2 0.2 1" />
      </material>
    </visual>
    <collision>
      <origin
        xyz="0 0 0"
        rpy="0 0 0" />
      <geometry>
        <mesh
          filename="package://quadruped_robot/meshes/rre_link.STL" />
      </geometry>
    </collision>
  </link>
  <joint
    name="rre_joint"
    type="revolute">
    <origin
      xyz="-0.026 2.5092E-05 -0.0292"
      rpy="0 -1.5708 0" />
    <parent
      link="rrs_link" />
    <child
      link="rre_link" />
    <axis
      xyz="0 0 -1" />
    <limit
      lower="-1.57"
      upper="1.57"
      effort="15"
      velocity="0.1" />
    <dynamics
      friction="0.1" />
  </joint>
  <link
    name="rrw_link">
    <inertial>
      <origin
        xyz="0.0327282618505259 -0.0371355920751884 0.024575333341552"
        rpy="0 0 0" />
      <mass
        value="0.0364534574348937" />
      <inertia
        ixx="3.3209124018188E-05"
        ixy="2.87264638709719E-05"
        ixz="2.58830403962932E-06"
        iyy="3.61939726921607E-05"
        iyz="-2.40711154137606E-06"
        izz="6.27932975779985E-05" />
    </inertial>
    <visual>
      <origin
        xyz="0 0 0"
        rpy="0 0 0" />
      <geometry>
        <mesh
          filename="package://quadruped_robot/meshes/rrw_link.STL" />
      </geometry>
      <material
        name="">
        <color
          rgba="0.2 0.2 0.2 1" />
      </material>
    </visual>
    <collision>
      <origin
        xyz="0 0 0"
        rpy="0 0 0" />
      <geometry>
        <mesh
          filename="package://quadruped_robot/meshes/rrw_link.STL" />
      </geometry>
    </collision>
  </link>
  <joint
    name="rrw_joint"
    type="revolute">
    <origin
      xyz="-0.0674292551030644 -0.0855834232709074 0.0120000007629388"
      rpy="0 0 0" />
    <parent
      link="rre_link" />
    <child
      link="rrw_link" />
    <axis
      xyz="0 0 -1" />
    <limit
      lower="-1.57"
      upper="1.57"
      effort="15"
      velocity="0.1" />
    <dynamics
      friction="0.1" />
  </joint>
  <link
    name="fls_link">
    <inertial>
      <origin
        xyz="-0.0163097792199962 -0.00505189850993423 -0.0274848378346823"
        rpy="0 0 0" />
      <mass
        value="0.0385206604865966" />
      <inertia
        ixx="8.71226998638337E-06"
        ixy="-4.1154824343927E-08"
        ixz="1.23274505726347E-10"
        iyy="5.1328533755997E-06"
        iyz="2.46844401583442E-07"
        izz="7.80628697106783E-06" />
    </inertial>
    <visual>
      <origin
        xyz="0 0 0"
        rpy="0 0 0" />
      <geometry>
        <mesh
          filename="package://quadruped_robot/meshes/fls_link.STL" />
      </geometry>
      <material
        name="">
        <color
          rgba="0.2 0.2 0.2 1" />
      </material>
    </visual>
    <collision>
      <origin
        xyz="0 0 0"
        rpy="0 0 0" />
      <geometry>
        <mesh
          filename="package://quadruped_robot/meshes/fls_link.STL" />
      </geometry>
    </collision>
  </link>
  <joint
    name="fls_joint"
    type="revolute">
    <origin
      xyz="0.0692381468948904 0.041436948075885 0"
      rpy="1.5707963267949 0 -1.5707963267949" />
    <parent
      link="body_link" />
    <child
      link="fls_link" />
    <axis
      xyz="0 0 -1" />
    <limit
      lower="-1.04"
      upper="1.04"
      effort="15"
      velocity="0.1" />
    <dynamics
      friction="0.1" />
  </joint>
  <link
    name="fle_link">
    <inertial>
      <origin
        xyz="0.0350678452252907 -0.0400605094902882 0.0318602163794606"
        rpy="0 0 0" />
      <mass
        value="0.0888795750621334" />
      <inertia
        ixx="5.33220086319603E-05"
        ixy="4.03152567305858E-05"
        ixz="-1.56293280951274E-07"
        iyy="5.5909435650468E-05"
        iyz="1.23774532447155E-06"
        izz="9.12913759529023E-05" />
    </inertial>
    <visual>
      <origin
        xyz="0 0 0"
        rpy="0 0 0" />
      <geometry>
        <mesh
          filename="package://quadruped_robot/meshes/fle_link.STL" />
      </geometry>
      <material
        name="">
        <color
          rgba="0.2 0.2 0.2 1" />
      </material>
    </visual>
    <collision>
      <origin
        xyz="0 0 0"
        rpy="0 0 0" />
      <geometry>
        <mesh
          filename="package://quadruped_robot/meshes/fle_link.STL" />
      </geometry>
    </collision>
  </link>
  <joint
    name="fle_joint"
    type="revolute">
    <origin
      xyz="-0.026 2.5E-05 -0.0292"
      rpy="0 -1.5708 0" />
    <parent
      link="fls_link" />
    <child
      link="fle_link" />
    <axis
      xyz="0 0 -1" />
    <limit
      lower="-1.57"
      upper="1.57"
      effort="15"
      velocity="0.1" />
    <dynamics
      friction="0.1" />
  </joint>
  <link
    name="flw_link">
    <inertial>
      <origin
        xyz="0.0334248441375446 0.0365098737154967 0.0245758218958261"
        rpy="0 0 0" />
      <mass
        value="0.0364534126206596" />
      <inertia
        ixx="3.21236278915475E-05"
        ixy="-2.86494262814616E-05"
        ixz="2.63338364661735E-06"
        iyy="3.72793853040095E-05"
        iyz="2.35772540129963E-06"
        izz="6.27932167217244E-05" />
    </inertial>
    <visual>
      <origin
        xyz="0 0 0"
        rpy="0 0 0" />
      <geometry>
        <mesh
          filename="package://quadruped_robot/meshes/flw_link.STL" />
      </geometry>
      <material
        name="">
        <color
          rgba="0.2 0.2 0.2 1" />
      </material>
    </visual>
    <collision>
      <origin
        xyz="0 0 0"
        rpy="0 0 0" />
      <geometry>
        <mesh
          filename="package://quadruped_robot/meshes/flw_link.STL" />
      </geometry>
    </collision>
  </link>
  <joint
    name="flw_joint"
    type="revolute">
    <origin
      xyz="0.0666437789549166 -0.0861964755789667 0.0120000007629387"
      rpy="0 0 3.14159265358979" />
    <parent
      link="fle_link" />
    <child
      link="flw_link" />
    <axis
      xyz="0 0 -1" />
    <limit
      lower="-1.57"
      upper="1.57"
      effort="15"
      velocity="0.1" />
    <dynamics
      friction="0.1" />
  </joint>
  <link
    name="rls_link">
    <inertial>
      <origin
        xyz="0.0163096392599824 -0.00505187347186335 -0.0274849143348058"
        rpy="0 0 0" />
      <mass
        value="0.0385204737997983" />
      <inertia
        ixx="8.71211945498261E-06"
        ixy="4.10847903075421E-08"
        ixz="-1.78152149763043E-10"
        iyy="5.13274302177549E-06"
        iyz="2.46917233525574E-07"
        izz="7.80614050595698E-06" />
    </inertial>
    <visual>
      <origin
        xyz="0 0 0"
        rpy="0 0 0" />
      <geometry>
        <mesh
          filename="package://quadruped_robot/meshes/rls_link.STL" />
      </geometry>
      <material
        name="">
        <color
          rgba="0.2 0.2 0.2 1" />
      </material>
    </visual>
    <collision>
      <origin
        xyz="0 0 0"
        rpy="0 0 0" />
      <geometry>
        <mesh
          filename="package://quadruped_robot/meshes/rls_link.STL" />
      </geometry>
    </collision>
  </link>
  <joint
    name="rls_joint"
    type="revolute">
    <origin
      xyz="-0.0677618531051057 0.0414371913110836 0"
      rpy="1.5707963267949 0 1.5707963267949" />
    <parent
      link="body_link" />
    <child
      link="rls_link" />
    <axis
      xyz="0 0 -1" />
    <limit
      lower="-1.04"
      upper="1.04"
      effort="15"
      velocity="0.1" />
    <dynamics
      friction="0.1" />
  </joint>
  <link
    name="rle_link">
    <inertial>
      <origin
        xyz="0.0356265571944218 -0.0395644610070837 0.0318602162662666"
        rpy="0 0 0" />
      <mass
        value="0.0888795712596426" />
      <inertia
        ixx="5.21911459681106E-05"
        ixy="4.02630729661195E-05"
        ixz="-1.73647215854727E-07"
        iyy="5.70402962740427E-05"
        iyz="1.23542947436058E-06"
        izz="9.12913750930588E-05" />
    </inertial>
    <visual>
      <origin
        xyz="0 0 0"
        rpy="0 0 0" />
      <geometry>
        <mesh
          filename="package://quadruped_robot/meshes/rle_link.STL" />
      </geometry>
      <material
        name="">
        <color
          rgba="0.2 0.2 0.2 1" />
      </material>
    </visual>
    <collision>
      <origin
        xyz="0 0 0"
        rpy="0 0 0" />
      <geometry>
        <mesh
          filename="package://quadruped_robot/meshes/rle_link.STL" />
      </geometry>
    </collision>
  </link>
  <joint
    name="rle_joint"
    type="revolute">
    <origin
      xyz="0.026 2.5117E-05 -0.0292"
      rpy="0 1.5708 0" />
    <parent
      link="rls_link" />
    <child
      link="rle_link" />
    <axis
      xyz="0 0 -1" />
    <limit
      lower="-1.57"
      upper="1.57"
      effort="15"
      velocity="0.1" />
    <dynamics
      friction="0.1" />
  </joint>
  <link
    name="rlw_link">
    <inertial>
      <origin
        xyz="-0.0329092151249457 -0.0369753287019312 0.0245758218509723"
        rpy="0 0 0" />
      <mass
        value="0.0364534139182269" />
      <inertia
        ixx="3.292863530567E-05"
        ixy="-2.87104862456198E-05"
        ixz="-2.60003851941444E-06"
        iyy="3.64743784614869E-05"
        iyz="-2.39444733312611E-06"
        izz="6.27932172557243E-05" />
    </inertial>
    <visual>
      <origin
        xyz="0 0 0"
        rpy="0 0 0" />
      <geometry>
        <mesh
          filename="package://quadruped_robot/meshes/rlw_link.STL" />
      </geometry>
      <material
        name="">
        <color
          rgba="0.298039215686275 0.298039215686275 0.298039215686275 1" />
      </material>
    </visual>
    <collision>
      <origin
        xyz="0 0 0"
        rpy="0 0 0" />
      <geometry>
        <mesh
          filename="package://quadruped_robot/meshes/rlw_link.STL" />
      </geometry>
    </collision>
  </link>
  <joint
    name="rlw_joint"
    type="revolute">
    <origin
      xyz="0.0678468062868589 -0.0852527803200612 0.0120000007629387"
      rpy="0 0 0" />
    <parent
      link="rle_link" />
    <child
      link="rlw_link" />
    <axis
      xyz="0 0 -1" />
    <limit
      lower="-1.57"
      upper="1.57"
      effort="15"
      velocity="0.1" />
    <dynamics
      friction="0.1" />
  </joint>
  <link
    name="lidar_link">
    <inertial>
      <origin
        xyz="-0.000358929753362797 6.73648551979822E-06 0.00597084128520243"
        rpy="0 0 0" />
      <mass
        value="0.0486570347493236" />
      <inertia
        ixx="8.03207199661195E-05"
        ixy="9.62728020214782E-10"
        ixz="-2.81787585091656E-06"
        iyy="4.73642808306099E-05"
        iyz="-1.31691164511042E-08"
        izz="6.64275155095978E-05" />
    </inertial>
    <visual>
      <origin
        xyz="0 0 0"
        rpy="0 0 0" />
      <geometry>
        <mesh
          filename="package://quadruped_robot/meshes/lidar_link.STL" />
      </geometry>
      <material
        name="">
        <color
          rgba="1 0.780392156862745 0.172549019607843 1" />
      </material>
    </visual>
    <collision>
      <origin
        xyz="0 0 0"
        rpy="0 0 0" />
      <geometry>
        <mesh
          filename="package://quadruped_robot/meshes/lidar_link.STL" />
      </geometry>
    </collision>
  </link>
  <joint
    name="lidar_joint"
    type="fixed">
    <origin
      xyz="0.13796897677403 0.00243727173357462 -0.0108941532533849"
      rpy="0 0 0" />
    <parent
      link="body_link" />
    <child
      link="lidar_link" />
    <axis
      xyz="0 0 0" />
  </joint>

  <gazebo>
    <plugin filename="libgazebo_ros2_control.so" name="gazebo_ros2_control">
      <parameters>$(find quadruped_robot)/config/control.yaml</parameters>
    </plugin>
  </gazebo>


  <ros2_control name="GazeboSystem" type="system">
    <hardware>
      <plugin>gazebo_ros2_control/GazeboSystem</plugin>
    </hardware> # Position Controller <joint
      name="frs_joint">
      <command_interface name="position">
        <param name="min">-3.14</param>
        <param name="max">3.14</param>
      </command_interface>
      <state_interface name="position" />
      <state_interface name="velocity" />
    </joint>

  <joint name="fre_joint">
      <command_interface name="position">
        <param name="min">-3.14</param>
        <param name="max">3.14</param>
      </command_interface>
      <state_interface name="position" />
      <state_interface name="velocity" />
    </joint>

 <joint name="frw_joint">
      <command_interface name="position">
        <param name="min">-3.14</param>
        <param name="max">3.14</param>
      </command_interface>
      <state_interface name="position" />
      <state_interface name="velocity" />
    </joint>

  <joint name="rrs_joint">
      <command_interface name="position">
        <param name="min">-3.14</param>
        <param name="max">3.14</param>
      </command_interface>
      <state_interface name="position" />
      <state_interface name="velocity" />
    </joint>

 <joint name="rre_joint">
      <command_interface name="position">
        <param name="min">-3.14</param>
        <param name="max">3.14</param>
      </command_interface>
      <state_interface name="position" />
      <state_interface name="velocity" />
    </joint>

  <joint name="rrw_joint">
      <command_interface name="position">
        <param name="min">-3.14</param>
        <param name="max">3.14</param>
      </command_interface>
      <state_interface name="position" />
      <state_interface name="velocity" />
    </joint>

 <joint name="fls_joint">
      <command_interface name="position">
        <param name="min">-3.14</param>
        <param name="max">3.14</param>
      </command_interface>
      <state_interface name="position" />
      <state_interface name="velocity" />
    </joint>

  <joint name="fle_joint">
      <command_interface name="position">
        <param name="min">-3.14</param>
        <param name="max">3.14</param>
      </command_interface>
      <state_interface name="position" />
      <state_interface name="velocity" />
    </joint>

  <joint name="flw_joint">
      <command_interface name="position">
        <param name="min">-3.14</param>
        <param name="max">3.14</param>
      </command_interface>
      <state_interface name="position" />
      <state_interface name="velocity" />
    </joint>

  <joint name="rls_joint">
      <command_interface name="position">
        <param name="min">-3.14</param>
        <param name="max">3.14</param>
      </command_interface>
      <state_interface name="position" />
      <state_interface name="velocity" />
    </joint>

 <joint name="rle_joint">
      <command_interface name="position">
        <param name="min">-3.14</param>
        <param name="max">3.14</param>
      </command_interface>
      <state_interface name="position" />
      <state_interface name="velocity" />
    </joint>

  <joint name="rlw_joint">
      <command_interface name="position">
        <param name="min">-3.14</param>
        <param name="max">3.14</param>
      </command_interface>
      <state_interface name="position" />
      <state_interface name="velocity" />
    </joint>

  </ros2_control>


</robot>